2022-09-17 23:52:18,835 :: ERROR -- C:\Users\Elena25\PycharmProjects\pythonProject\venv\lib\site-packages\django\utils\log.py / (<class 'django.template.exceptions.TemplateDoesNotExist'>, TemplateDoesNotExist('news/post_category.html, news/category_list.html'), <traceback object at 0x000000DDA9528980>) :Internal Server Error: /news/subscribe/
Traceback (most recent call last):
  File "C:\Users\Elena25\PycharmProjects\pythonProject\venv\lib\site-packages\django\core\handlers\exception.py", line 55, in inner
    response = get_response(request)
  File "C:\Users\Elena25\PycharmProjects\pythonProject\venv\lib\site-packages\django\core\handlers\base.py", line 220, in _get_response
    response = response.render()
  File "C:\Users\Elena25\PycharmProjects\pythonProject\venv\lib\site-packages\django\template\response.py", line 114, in render
    self.content = self.rendered_content
  File "C:\Users\Elena25\PycharmProjects\pythonProject\venv\lib\site-packages\django\template\response.py", line 90, in rendered_content
    template = self.resolve_template(self.template_name)
  File "C:\Users\Elena25\PycharmProjects\pythonProject\venv\lib\site-packages\django\template\response.py", line 72, in resolve_template
    return select_template(template, using=self.using)
  File "C:\Users\Elena25\PycharmProjects\pythonProject\venv\lib\site-packages\django\template\loader.py", line 47, in select_template
    raise TemplateDoesNotExist(", ".join(template_name_list), chain=chain)
django.template.exceptions.TemplateDoesNotExist: news/post_category.html, news/category_list.html
2022-09-17 23:52:18,837 :: ERROR -- C:\Users\Elena25\PycharmProjects\pythonProject\venv\lib\site-packages\django\core\servers\basehttp.py / None :"GET /news/subscribe/ HTTP/1.1" 500 88864
2022-09-17 23:52:35,959 :: ERROR -- C:\Users\Elena25\PycharmProjects\pythonProject\venv\lib\site-packages\django\utils\log.py / (<class 'django.template.exceptions.TemplateDoesNotExist'>, TemplateDoesNotExist('news/post_category.html, news/category_list.html'), <traceback object at 0x000000DDA9651540>) :Internal Server Error: /news/subscribe/
Traceback (most recent call last):
  File "C:\Users\Elena25\PycharmProjects\pythonProject\venv\lib\site-packages\django\core\handlers\exception.py", line 55, in inner
    response = get_response(request)
  File "C:\Users\Elena25\PycharmProjects\pythonProject\venv\lib\site-packages\django\core\handlers\base.py", line 220, in _get_response
    response = response.render()
  File "C:\Users\Elena25\PycharmProjects\pythonProject\venv\lib\site-packages\django\template\response.py", line 114, in render
    self.content = self.rendered_content
  File "C:\Users\Elena25\PycharmProjects\pythonProject\venv\lib\site-packages\django\template\response.py", line 90, in rendered_content
    template = self.resolve_template(self.template_name)
  File "C:\Users\Elena25\PycharmProjects\pythonProject\venv\lib\site-packages\django\template\response.py", line 72, in resolve_template
    return select_template(template, using=self.using)
  File "C:\Users\Elena25\PycharmProjects\pythonProject\venv\lib\site-packages\django\template\loader.py", line 47, in select_template
    raise TemplateDoesNotExist(", ".join(template_name_list), chain=chain)
django.template.exceptions.TemplateDoesNotExist: news/post_category.html, news/category_list.html
2022-09-17 23:52:35,961 :: ERROR -- C:\Users\Elena25\PycharmProjects\pythonProject\venv\lib\site-packages\django\core\servers\basehttp.py / None :"GET /news/subscribe/ HTTP/1.1" 500 88864
